---
title: Usando exceções – Guia de Programação em C#
description: Saiba como usar exceções. As exceções são geradas pelo código que encontra um erro e detectadas pelo código que corrige o erro.
ms.date: 12/09/2020
helpviewer_keywords:
- exception handling [C#], about exception handling
- exceptions [C#], about exceptions
ms.assetid: 71472c62-320a-470a-97d2-67995180389d
ms.openlocfilehash: 30a7c3eecb599493dfa74d664c4899836c1b9276
ms.sourcegitcommit: 9b877e160c326577e8aa5ead22a937110d80fa44
ms.translationtype: MT
ms.contentlocale: pt-BR
ms.lasthandoff: 12/11/2020
ms.locfileid: "97110215"
---
# <a name="use-exceptions-c-programming-guide"></a><span data-ttu-id="03271-104">Usar exceções (guia de programação C#)</span><span class="sxs-lookup"><span data-stu-id="03271-104">Use exceptions (C# programming guide)</span></span>

<span data-ttu-id="03271-105">No C#, os erros no programa em tempo de execução são propagados pelo programa usando um mecanismo chamado exceções.</span><span class="sxs-lookup"><span data-stu-id="03271-105">In C#, errors in the program at run time are propagated through the program by using a mechanism called exceptions.</span></span> <span data-ttu-id="03271-106">As exceções são geradas pelo código que encontra um erro e capturadas pelo código que pode corrigir o erro.</span><span class="sxs-lookup"><span data-stu-id="03271-106">Exceptions are thrown by code that encounters an error and caught by code that can correct the error.</span></span> <span data-ttu-id="03271-107">As exceções podem ser geradas pelo tempo de execução do .NET ou pelo código em um programa.</span><span class="sxs-lookup"><span data-stu-id="03271-107">Exceptions can be thrown by the .NET runtime or by code in a program.</span></span> <span data-ttu-id="03271-108">Uma vez que uma exceção é gerada, ela é propagada acima na pilha de chamadas até uma instrução `catch` para a exceção ser encontrada.</span><span class="sxs-lookup"><span data-stu-id="03271-108">Once an exception is thrown, it propagates up the call stack until a `catch` statement for the exception is found.</span></span> <span data-ttu-id="03271-109">As exceções não capturadas são tratadas por um manipulador de exceção genérico fornecido pelo sistema que exibe uma caixa de diálogo.</span><span class="sxs-lookup"><span data-stu-id="03271-109">Uncaught exceptions are handled by a generic exception handler provided by the system that displays a dialog box.</span></span>

<span data-ttu-id="03271-110">As exceções são representadas por classes derivadas de <xref:System.Exception>.</span><span class="sxs-lookup"><span data-stu-id="03271-110">Exceptions are represented by classes derived from <xref:System.Exception>.</span></span> <span data-ttu-id="03271-111">Essa classe identifica o tipo de exceção e contém propriedades que têm detalhes sobre a exceção.</span><span class="sxs-lookup"><span data-stu-id="03271-111">This class identifies the type of exception and contains properties that have details about the exception.</span></span> <span data-ttu-id="03271-112">Gerar uma exceção envolve criar uma instância de uma classe derivada de exceção, opcionalmente configurar propriedades da exceção e, em seguida, gerar o objeto usando a palavra-chave `throw`.</span><span class="sxs-lookup"><span data-stu-id="03271-112">Throwing an exception involves creating an instance of an exception-derived class, optionally configuring properties of the exception, and then throwing the object by using the `throw` keyword.</span></span> <span data-ttu-id="03271-113">Por exemplo:</span><span class="sxs-lookup"><span data-stu-id="03271-113">For example:</span></span>

:::code language="csharp" source="snippets/exceptions/Program.cs" id="ThrowException":::

<span data-ttu-id="03271-114">Depois que uma exceção é gerada, o runtime verifica a instrução atual para ver se ela está dentro de um bloco `try`.</span><span class="sxs-lookup"><span data-stu-id="03271-114">After an exception is thrown, the runtime checks the current statement to see whether it is within a `try` block.</span></span> <span data-ttu-id="03271-115">Se estiver, todos os blocos `catch` associados ao bloco `try` serão verificados para ver se eles podem capturar a exceção.</span><span class="sxs-lookup"><span data-stu-id="03271-115">If it is, any `catch` blocks associated with the `try` block are checked to see whether they can catch the exception.</span></span> <span data-ttu-id="03271-116">Os blocos `Catch` normalmente especificam os tipos de exceção. Se o tipo do bloco `catch` for do mesmo tipo que a exceção ou uma classe base da exceção, o bloco `catch` poderá manipular o método.</span><span class="sxs-lookup"><span data-stu-id="03271-116">`Catch` blocks typically specify exception types; if the type of the `catch` block is the same type as the exception, or a base class of the exception, the `catch` block can handle the method.</span></span> <span data-ttu-id="03271-117">Por exemplo:</span><span class="sxs-lookup"><span data-stu-id="03271-117">For example:</span></span>

:::code language="csharp" source="snippets/exceptions/Program.cs" id="CatchException":::

<span data-ttu-id="03271-118">Se a instrução que gera uma exceção não está dentro de um `try` bloco ou se o `try` bloco que o inclui não tem nenhum `catch` bloco correspondente, o tempo de execução verifica o método de chamada para uma `try` instrução e `catch` blocos.</span><span class="sxs-lookup"><span data-stu-id="03271-118">If the statement that throws an exception isn't within a `try` block or if the `try` block that encloses it has no matching `catch` block, the runtime checks the calling method for a `try` statement and `catch` blocks.</span></span> <span data-ttu-id="03271-119">O runtime continuará acima na pilha de chamada, pesquisando um bloco `catch` compatível.</span><span class="sxs-lookup"><span data-stu-id="03271-119">The runtime continues up the calling stack, searching for a compatible `catch` block.</span></span> <span data-ttu-id="03271-120">Depois que o bloco `catch` for localizado e executado, o controle será passado para a próxima instrução após aquele bloco `catch`.</span><span class="sxs-lookup"><span data-stu-id="03271-120">After the `catch` block is found and executed, control is passed to the next statement after that `catch` block.</span></span>

<span data-ttu-id="03271-121">Uma instrução `try` pode conter mais de um bloco `catch`.</span><span class="sxs-lookup"><span data-stu-id="03271-121">A `try` statement can contain more than one `catch` block.</span></span> <span data-ttu-id="03271-122">A primeira `catch` instrução que pode manipular a exceção é executada; qualquer instrução a seguir `catch` , mesmo se for compatível, será ignorada.</span><span class="sxs-lookup"><span data-stu-id="03271-122">The first `catch` statement that can handle the exception is executed; any following `catch` statements, even if they're compatible, are ignored.</span></span> <span data-ttu-id="03271-123">Os blocos catch devem ser sempre ordenados do mais específico (ou mais derivado) para o menos específico.</span><span class="sxs-lookup"><span data-stu-id="03271-123">Catch blocks should always be ordered from most specific (or most-derived) to least specific.</span></span> <span data-ttu-id="03271-124">Por exemplo:</span><span class="sxs-lookup"><span data-stu-id="03271-124">For example:</span></span>

:::code language="csharp" source="snippets/exceptions/CatchOrder.cs":::

<span data-ttu-id="03271-125">Antes de o bloco `catch` ser executado, o runtime verifica se há blocos `finally`.</span><span class="sxs-lookup"><span data-stu-id="03271-125">Before the `catch` block is executed, the runtime checks for `finally` blocks.</span></span> <span data-ttu-id="03271-126">`Finally` os blocos permitem que o programador limpe qualquer estado ambíguo que pudesse ser deixado de um bloco anulado `try` ou libere recursos externos (como identificadores gráficos, conexões de banco de dados ou fluxos de arquivos) sem esperar que o coletor de lixo no tempo de execução Finalize os objetos.</span><span class="sxs-lookup"><span data-stu-id="03271-126">`Finally` blocks enable the programmer to clean up any ambiguous state that could be left over from an aborted `try` block, or to release any external resources (such as graphics handles, database connections, or file streams) without waiting for the garbage collector in the runtime to finalize the objects.</span></span> <span data-ttu-id="03271-127">Por exemplo:</span><span class="sxs-lookup"><span data-stu-id="03271-127">For example:</span></span>

:::code language="csharp" source="snippets/exceptions/Program.cs" id="TestFinally":::

<span data-ttu-id="03271-128">Se `WriteByte()` o lançou uma exceção, o código no segundo `try` bloco que tentar reabrir o arquivo falhará se `file.Close()` não for chamado, e o arquivo permanecerá bloqueado.</span><span class="sxs-lookup"><span data-stu-id="03271-128">If `WriteByte()` threw an exception, the code in the second `try` block that tries to reopen the file would fail if `file.Close()` isn't called, and the file would remain locked.</span></span> <span data-ttu-id="03271-129">Como os blocos `finally` são executados mesmo se uma exceção for gerada, o bloco `finally` no exemplo anterior permite que o arquivo seja fechado corretamente e ajuda a evitar um erro.</span><span class="sxs-lookup"><span data-stu-id="03271-129">Because `finally` blocks are executed even if an exception is thrown, the `finally` block in the previous example allows for the file to be closed correctly and helps avoid an error.</span></span>

<span data-ttu-id="03271-130">Se não for encontrado nenhum bloco `catch` compatível na pilha de chamadas após uma exceção ser gerada, ocorrerá uma das três coisas:</span><span class="sxs-lookup"><span data-stu-id="03271-130">If no compatible `catch` block is found on the call stack after an exception is thrown, one of three things occurs:</span></span>

- <span data-ttu-id="03271-131">Se a exceção estiver em um finalizador, o finalizador será anulado e o finalizador base, se houver, será chamado.</span><span class="sxs-lookup"><span data-stu-id="03271-131">If the exception is within a finalizer, the finalizer is aborted and the base finalizer, if any, is called.</span></span>
- <span data-ttu-id="03271-132">Se a pilha de chamadas contiver um construtor estático ou um inicializador de campo estático, uma <xref:System.TypeInitializationException> será gerada, com a exceção original atribuída à propriedade <xref:System.Exception.InnerException%2A> da nova exceção.</span><span class="sxs-lookup"><span data-stu-id="03271-132">If the call stack contains a static constructor, or a static field initializer, a <xref:System.TypeInitializationException> is thrown, with the original exception assigned to the <xref:System.Exception.InnerException%2A> property of the new exception.</span></span>
- <span data-ttu-id="03271-133">Se o início do thread for atingido, o thread será encerrado.</span><span class="sxs-lookup"><span data-stu-id="03271-133">If the start of the thread is reached, the thread is terminated.</span></span>
